<?xml version="1.0"?>
<robot xmlns:xacro="http://www.ros.org/wiki/xacro" >

  <link name="base_link">
  </link>
  <link name="chassis">
    <inertial>
      <origin
        xyz="0.082664 -0.00032308 0.0045523"
        rpy="0 0 0" />
      <mass
        value="0.80581" />
      <inertia
        ixx="0.0008436"
        ixy="3.5973E-07"
        ixz="3.1609E-21"
        iyy="0.0019625"
        iyz="-5.6881E-22"
        izz="0.0027709" />
    </inertial>
    <visual>
      <origin
        xyz="0.125 0 0.025"
        rpy="0 0 0" />
      <geometry>
        <box size="0.25 0.15 0.05"/>
      </geometry>
      <material
        name="">
        <color
          rgba="0.79216 0.81961 0.93333 1" />
      </material>
    </visual>
    <collision>
      <origin
        xyz="0.125 0 0.025"
        rpy="0 0 0" />
      <geometry>
        <box size="0.25 0.15 0.05"/>
      </geometry>
    </collision>
  </link>
  <joint name="chassis_joint"
    type="fixed">
    <origin
      xyz="-0.04 3.8262E-05 0.02"
      rpy="0 0 0" />
    <parent
      link="base_link" />
    <child
      link="chassis" />
    <axis
      xyz="0 0 0" />
  </joint>
  <link name="caster_wheel">
    <inertial>
      <origin
        xyz="0 0 0.0030103"
        rpy="0 0 0" />
      <mass
        value="0.0036843" />
      <inertia
        ixx="1.6553E-07"
        ixy="2.6765E-16"
        ixz="-3.43E-23"
        iyy="1.3764E-07"
        iyz="-4.1716E-23"
        izz="2.4862E-07" />
    </inertial>
    <visual>
      <origin
        xyz="0 0 0"
        rpy="0 0 0" />
      <geometry>
          <sphere radius="0.007"/>
      </geometry>
      <material
        name="">
        <color
          rgba="0.79216 0.81961 0.93333 1" />
      </material>
    </visual>
    <collision>
      <origin
        xyz="0 0 0"
        rpy="0 0 0" />
      <geometry>
          <sphere radius="0.007"/>
      </geometry>
    </collision>
  </link>
  <joint name="caster_wheel_joint"
    type="fixed">
    <origin
      xyz="0.22 -0.00014975 -0.0476"
      rpy="0 0 0" />
    <parent
      link="chassis" />
    <child
      link="caster_wheel" />
    <axis
      xyz="0 0 0" />
  </joint>

  <link name="left_wheel">
    <inertial>
      <origin
        xyz="1.3946E-08 -0.007373 -1.2357E-08"
        rpy="0 0 0" />
      <mass
        value="0.022902" />
      <inertia
        ixx="9.2315E-06"
        ixy="-3.296E-13"
        ixz="-2.4757E-10"
        iyy="1.553E-05"
        iyz="2.9149E-13"
        izz="9.2314E-06" />
    </inertial>
    <visual>
      <origin
        xyz="0 0 0"
        rpy="0 0 0" />
      <geometry>
        <mesh
          filename="file:$(find my_mobrob)/meshes/left_wheel.STL" />
      </geometry>
      <material
        name="">
        <color
          rgba="0.79216 0.81961 0.93333 1" />
      </material>
    </visual>
    <collision>
      <origin
        xyz="0 8.6E-03 0"
        rpy="0 0 0" />
      <geometry>
        <mesh
          filename="file:$(find my_mobrob)/meshes/left_wheel.STL" />
      </geometry>
    </collision>
  </link>

  <joint name="left_wheel_joint"
    type="continuous">
    <origin
      xyz="0 0.10139 0"
      rpy="0 0 0" />
    <parent
      link="base_link" />
    <child
      link="left_wheel" />
    <axis
      xyz="0 1 0" />
  </joint>

  <link name="right_wheel">
    <inertial>
      <origin
        xyz="2.5267E-09 0.007373 1.8461E-08"
        rpy="0 0 0" />
      <mass
        value="0.022902" />
      <inertia
        ixx="9.2312E-06"
        ixy="6.0082E-14"
        ixz="1.0223E-10"
        iyy="1.553E-05"
        iyz="4.3588E-13"
        izz="9.2317E-06" />
    </inertial>
    <visual>
      <origin
        xyz="0 0 0"
        rpy="0 0 0" />
      <geometry>
        <mesh
          filename="file:$(find my_mobrob)/meshes/right_wheel.STL" />
      </geometry>
      <material
        name="">
        <color
          rgba="0.79216 0.81961 0.93333 1" />
      </material>
    </visual>
    <collision>
      <origin
        xyz="0 0 0"
        rpy="0 0 0" />
      <geometry>
        <mesh
          filename="file:$(find my_mobrob)/meshes/right_wheel.STL" />
      </geometry>
    </collision>
  </link>
  
  <joint name="right_wheel_joint"
    type="continuous">
    <origin
      xyz="0 -0.10161 0"
      rpy="0 0 0" />
    <parent
      link="base_link" />
    <child
      link="right_wheel" />
    <axis
      xyz="0 1 0" />
  </joint>
    
</robot> 